Workbook

Sheet Sheet2
A1: Total # Of Companies
A2: Convenience Stores / Gas Stations | D2: Companies | E2: =SUM(SIGN(FREQUENCY(IFERROR(IF('Data Dump'!$A:$A=Sheet2!A2,MATCH('Data Dump'!$B:$B,'Data Dump'!$B:$B,0)),""),ROW('Data Dump'!$A$1:$A$2000)-ROW('Data Dump'!$A$1)+1))) -> 1 | G2: Michael Donohue | J2: Companies | K2: =SUM(SIGN(FREQUENCY(IFERROR(IF('Data Dump'!$C:$C=Sheet2!G2,MATCH('Data Dump'!$B:$B,'Data Dump'!$B:$B,0)),""),ROW('Data Dump'!$A$1:$A$2000)-ROW('Data Dump'!$A$1)+1))) -> 1
A3: Open - Not Contacted | C3: =SUM(SIGN(FREQUENCY(IFERROR(IF('Data Dump'!A:A=A2,MATCH('Data Dump'!B:B,'Data Dump'!B:B,0)),""),ROW('Data Dump'!A1:A1000)-ROW('Data Dump'!A1)+1))) -> 1 | D3: =ROUND((C3/$E$2),2) -> 1 | E3: =C3&" / "&D3 -> 1 / 1 | G3: Open - Not Contacted | I3: =SUM(SIGN(FREQUENCY(IFERROR(IF('Data Dump'!G:G=G2,MATCH('Data Dump'!H:H,'Data Dump'!H:H,0)),""),ROW('Data Dump'!G1:G1000)-ROW('Data Dump'!G1)+1))) -> #VALUE! | J3: =ROUND((I3/$E$2),2) -> #VALUE! | K3: =I3&" / "&J3 -> #VALUE!
A4: Actively Working | C4: =COUNTIFS('Data Dump'!$A:$A,Sheet2!$A$2,'Data Dump'!$F:$F,Sheet2!A4) -> 41 | D4: =ROUND((C4/$E$2),2) -> 41 | E4: =C4&" / "&D4 -> 41 / 41 | G4: Actively Working | I4: =COUNTIFS('Data Dump'!$A:$A,Sheet2!$A$2,'Data Dump'!$F:$F,Sheet2!G4) -> 41 | J4: =ROUND((I4/$E$2),2) -> 41 | K4: =I4&" / "&J4 -> 41 / 41
A5: Nurturing | C5: =COUNTIFS('Data Dump'!$A:$A,Sheet2!$A$2,'Data Dump'!$F:$F,Sheet2!A5) -> 16 | D5: =ROUND((C5/$E$2),2) -> 16 | E5: =C5&" / "&D5 -> 16 / 16 | G5: Nurturing | I5: =COUNTIFS('Data Dump'!$A:$A,Sheet2!$A$2,'Data Dump'!$F:$F,Sheet2!G5) -> 16 | J5: =ROUND((I5/$E$2),2) -> 16 | K5: =I5&" / "&J5 -> 16 / 16
A6: Unqualified | C6: =COUNTIFS('Data Dump'!$A:$A,Sheet2!$A$2,'Data Dump'!$F:$F,Sheet2!A6) -> 8 | D6: =ROUND((C6/$E$2),2) -> 8 | E6: =C6&" / "&D6 -> 8 / 8 | G6: Unqualified | I6: =COUNTIFS('Data Dump'!$A:$A,Sheet2!$A$2,'Data Dump'!$F:$F,Sheet2!G6) -> 8 | J6: =ROUND((I6/$E$2),2) -> 8 | K6: =I6&" / "&J6 -> 8 / 8
A7: Restaurants - Full Serve / Casual Dining | E7: =SUM(SIGN(FREQUENCY(IFERROR(IF('Data Dump'!A:A=Sheet2!A7,MATCH('Data Dump'!B:B,'Data Dump'!B:B,0)),""),ROW('Data Dump'!$A$1:$A$2000)-ROW('Data Dump'!$A$1)+1))) -> #VALUE! | G7: Matt Creager | K7: =SUM(SIGN(FREQUENCY(IFERROR(IF('Data Dump'!C:C=Sheet2!G7,MATCH('Data Dump'!B:B,'Data Dump'!B:B,0)),""),ROW('Data Dump'!$A$1:$A$2000)-ROW('Data Dump'!$A$1)+1))) -> #VALUE!
A8: Open - Not Contacted | G8: Open - Not Contacted
A9: Actively Working | C9: =COUNTIFS('Data Dump'!$A:$A,Sheet2!$A$7,'Data Dump'!$F:$F,Sheet2!A9) -> 24 | D9: =ROUND((C9/$E$7),2) -> #VALUE! | E9: =C9&" / "&D9 -> #VALUE! | G9: Actively Working | I9: =COUNTIFS('Data Dump'!$A:$A,Sheet2!$A$7,'Data Dump'!$F:$F,Sheet2!G9) -> 24 | J9: =ROUND((I9/$E$7),2) -> #VALUE! | K9: =I9&" / "&J9 -> #VALUE!
A10: Nurturing | C10: =COUNTIFS('Data Dump'!$A:$A,Sheet2!$A$7,'Data Dump'!$F:$F,Sheet2!A10) -> 6 | D10: =ROUND((C10/$E$7),2) -> #VALUE! | E10: =C10&" / "&D10 -> #VALUE! | G10: Nurturing | I10: =COUNTIFS('Data Dump'!$A:$A,Sheet2!$A$7,'Data Dump'!$F:$F,Sheet2!G10) -> 6 | J10: =ROUND((I10/$E$7),2) -> #VALUE! | K10: =I10&" / "&J10 -> #VALUE!
A11: Unqualified | C11: =COUNTIFS('Data Dump'!$A:$A,Sheet2!$A$7,'Data Dump'!$F:$F,Sheet2!A11) -> 20 | D11: =ROUND((C11/$E$7),2) -> #VALUE! | E11: =C11&" / "&D11 -> #VALUE! | G11: Unqualified | I11: =COUNTIFS('Data Dump'!$A:$A,Sheet2!$A$7,'Data Dump'!$F:$F,Sheet2!G11) -> 20 | J11: =ROUND((I11/$E$7),2) -> #VALUE! | K11: =I11&" / "&J11 -> #VALUE!
A12: Restaurants - Quick Serve / Fast Food | E12: =SUM(SIGN(FREQUENCY(IFERROR(IF('Data Dump'!A:A=Sheet2!A12,MATCH('Data Dump'!B:B,'Data Dump'!B:B,0)),""),ROW('Data Dump'!$A$1:$A$2000)-ROW('Data Dump'!$A$1)+1))) -> #VALUE! | G12: Steven Shartzer | K12: =SUM(SIGN(FREQUENCY(IFERROR(IF('Data Dump'!C:C=Sheet2!G12,MATCH('Data Dump'!B:B,'Data Dump'!B:B,0)),""),ROW('Data Dump'!$A$1:$A$2000)-ROW('Data Dump'!$A$1)+1))) -> #VALUE!
A13: Open - Not Contacted | G13: Open - Not Contacted
A14: Actively Working | C14: =COUNTIFS('Data Dump'!$A:$A,Sheet2!$A$12,'Data Dump'!$F:$F,Sheet2!A14) -> 24 | D14: =ROUND((C14/$E$12),2) -> #VALUE! | E14: =C14&" / "&D14 -> #VALUE! | G14: Actively Working | I14: =COUNTIFS('Data Dump'!$A:$A,Sheet2!$A$12,'Data Dump'!$F:$F,Sheet2!G14) -> 24 | J14: =ROUND((I14/$E$12),2) -> #VALUE! | K14: =I14&" / "&J14 -> #VALUE!
A15: Nurturing | C15: =COUNTIFS('Data Dump'!$A:$A,Sheet2!$A$12,'Data Dump'!$F:$F,Sheet2!A15) -> 2 | D15: =ROUND((C15/$E$12),2) -> #VALUE! | E15: =C15&" / "&D15 -> #VALUE! | G15: Nurturing | I15: =COUNTIFS('Data Dump'!$A:$A,Sheet2!$A$12,'Data Dump'!$F:$F,Sheet2!G15) -> 2 | J15: =ROUND((I15/$E$12),2) -> #VALUE! | K15: =I15&" / "&J15 -> #VALUE!
A16: Unqualified | C16: =COUNTIFS('Data Dump'!$A:$A,Sheet2!$A$12,'Data Dump'!$F:$F,Sheet2!A16) -> 2 | D16: =ROUND((C16/$E$12),2) -> #VALUE! | E16: =C16&" / "&D16 -> #VALUE! | G16: Unqualified | I16: =COUNTIFS('Data Dump'!$A:$A,Sheet2!$A$12,'Data Dump'!$F:$F,Sheet2!G16) -> 2 | J16: =ROUND((I16/$E$12),2) -> #VALUE! | K16: =I16&" / "&J16 -> #VALUE!
A17: Retail - Big Box | E17: =SUM(SIGN(FREQUENCY(IFERROR(IF('Data Dump'!A:A=Sheet2!A17,MATCH('Data Dump'!B:B,'Data Dump'!B:B,0)),""),ROW('Data Dump'!$A$1:$A$2000)-ROW('Data Dump'!$A$1)+1))) -> #VALUE! | G17: Robert Giblett | K17: =SUM(SIGN(FREQUENCY(IFERROR(IF('Data Dump'!C:C=Sheet2!G17,MATCH('Data Dump'!B:B,'Data Dump'!B:B,0)),""),ROW('Data Dump'!$A$1:$A$2000)-ROW('Data Dump'!$A$1)+1))) -> #VALUE!
A18: Open - Not Contacted | G18: Open - Not Contacted
A19: Actively Working | C19: =COUNTIFS('Data Dump'!$A:$A,Sheet2!$A$17,'Data Dump'!$F:$F,Sheet2!A19) -> 35 | D19: =ROUND((C19/$E$17),2) -> #VALUE! | E19: =C19&" / "&D19 -> #VALUE! | G19: Actively Working | I19: =COUNTIFS('Data Dump'!$A:$A,Sheet2!$A$17,'Data Dump'!$F:$F,Sheet2!G19) -> 35 | J19: =ROUND((I19/$E$17),2) -> #VALUE! | K19: =I19&" / "&J19 -> #VALUE!
A20: Nurturing | C20: =COUNTIFS('Data Dump'!$A:$A,Sheet2!$A$17,'Data Dump'!$F:$F,Sheet2!A20) -> 0 | D20: =ROUND((C20/$E$17),2) -> #VALUE! | E20: =C20&" / "&D20 -> #VALUE! | G20: Nurturing | I20: =COUNTIFS('Data Dump'!$A:$A,Sheet2!$A$17,'Data Dump'!$F:$F,Sheet2!G20) -> 0 | J20: =ROUND((I20/$E$17),2) -> #VALUE! | K20: =I20&" / "&J20 -> #VALUE!
A21: Unqualified | C21: =COUNTIFS('Data Dump'!$A:$A,Sheet2!$A$17,'Data Dump'!$F:$F,Sheet2!A21) -> 6 | D21: =ROUND((C21/$E$17),2) -> #VALUE! | E21: =C21&" / "&D21 -> #VALUE! | G21: Unqualified | I21: =COUNTIFS('Data Dump'!$A:$A,Sheet2!$A$17,'Data Dump'!$F:$F,Sheet2!G21) -> 6 | J21: =ROUND((I21/$E$17),2) -> #VALUE! | K21: =I21&" / "&J21 -> #VALUE!
A22: Retail - Grocery | E22: =SUM(SIGN(FREQUENCY(IFERROR(IF('Data Dump'!A:A=Sheet2!A22,MATCH('Data Dump'!B:B,'Data Dump'!B:B,0)),""),ROW('Data Dump'!$A$1:$A$2000)-ROW('Data Dump'!$A$1)+1))) -> #VALUE! | G22: Allen Scott | K22: =SUM(SIGN(FREQUENCY(IFERROR(IF('Data Dump'!C:C=Sheet2!G22,MATCH('Data Dump'!B:B,'Data Dump'!B:B,0)),""),ROW('Data Dump'!$A$1:$A$2000)-ROW('Data Dump'!$A$1)+1))) -> #VALUE!
A23: Open - Not Contacted | G23: Open - Not Contacted
A24: Actively Working | C24: =COUNTIFS('Data Dump'!$A:$A,Sheet2!$A$22,'Data Dump'!$F:$F,Sheet2!A24) -> 87 | D24: =ROUND((C24/$E$22),2) -> #VALUE! | E24: =C24&" / "&D24 -> #VALUE! | G24: Actively Working | I24: =COUNTIFS('Data Dump'!$A:$A,Sheet2!$A$22,'Data Dump'!$F:$F,Sheet2!G24) -> 87 | J24: =ROUND((I24/$E$22),2) -> #VALUE! | K24: =I24&" / "&J24 -> #VALUE!
A25: Nurturing | C25: =COUNTIFS('Data Dump'!$A:$A,Sheet2!$A$22,'Data Dump'!$F:$F,Sheet2!A25) -> 7 | D25: =ROUND((C25/$E$22),2) -> #VALUE! | E25: =C25&" / "&D25 -> #VALUE! | G25: Nurturing | I25: =COUNTIFS('Data Dump'!$A:$A,Sheet2!$A$22,'Data Dump'!$F:$F,Sheet2!G25) -> 7 | J25: =ROUND((I25/$E$22),2) -> #VALUE! | K25: =I25&" / "&J25 -> #VALUE!
A26: Unqualified | C26: =COUNTIFS('Data Dump'!$A:$A,Sheet2!$A$22,'Data Dump'!$F:$F,Sheet2!A26) -> 1 | D26: =ROUND((C26/$E$22),2) -> #VALUE! | E26: =C26&" / "&D26 -> #VALUE! | G26: Unqualified | I26: =COUNTIFS('Data Dump'!$A:$A,Sheet2!$A$22,'Data Dump'!$F:$F,Sheet2!G26) -> 1 | J26: =ROUND((I26/$E$22),2) -> #VALUE! | K26: =I26&" / "&J26 -> #VALUE!
A27: Retail - Medium Box | E27: =SUM(SIGN(FREQUENCY(IFERROR(IF('Data Dump'!A:A=Sheet2!A27,MATCH('Data Dump'!B:B,'Data Dump'!B:B,0)),""),ROW('Data Dump'!$A$1:$A$2000)-ROW('Data Dump'!$A$1)+1))) -> #VALUE! | G27: Mike Pluff | K27: =SUM(SIGN(FREQUENCY(IFERROR(IF('Data Dump'!C:C=Sheet2!G27,MATCH('Data Dump'!B:B,'Data Dump'!B:B,0)),""),ROW('Data Dump'!$A$1:$A$2000)-ROW('Data Dump'!$A$1)+1))) -> #VALUE!
A28: Open - Not Contacted | G28: Open - Not Contacted
A29: Actively Working | C29: =COUNTIFS('Data Dump'!$A:$A,Sheet2!$A$27,'Data Dump'!$F:$F,Sheet2!A29) -> 29 | D29: =ROUND((C29/$E$27),2) -> #VALUE! | E29: =C29&" / "&D29 -> #VALUE! | G29: Actively Working | I29: =COUNTIFS('Data Dump'!$A:$A,Sheet2!$A$27,'Data Dump'!$F:$F,Sheet2!G29) -> 29 | J29: =ROUND((I29/$E$27),2) -> #VALUE! | K29: =I29&" / "&J29 -> #VALUE!
A30: Nurturing | C30: =COUNTIFS('Data Dump'!$A:$A,Sheet2!$A$27,'Data Dump'!$F:$F,Sheet2!A30) -> 2 | D30: =ROUND((C30/$E$27),2) -> #VALUE! | E30: =C30&" / "&D30 -> #VALUE! | G30: Nurturing | I30: =COUNTIFS('Data Dump'!$A:$A,Sheet2!$A$27,'Data Dump'!$F:$F,Sheet2!G30) -> 2 | J30: =ROUND((I30/$E$27),2) -> #VALUE! | K30: =I30&" / "&J30 -> #VALUE!
A31: Unqualified | C31: =COUNTIFS('Data Dump'!$A:$A,Sheet2!$A$27,'Data Dump'!$F:$F,Sheet2!A31) -> 1 | D31: =ROUND((C31/$E$27),2) -> #VALUE! | E31: =C31&" / "&D31 -> #VALUE! | G31: Unqualified | I31: =COUNTIFS('Data Dump'!$A:$A,Sheet2!$A$27,'Data Dump'!$F:$F,Sheet2!G31) -> 1 | J31: =ROUND((I31/$E$27),2) -> #VALUE! | K31: =I31&" / "&J31 -> #VALUE!
A32: Retail - Pharmacy | E32: =SUM(SIGN(FREQUENCY(IFERROR(IF('Data Dump'!A:A=Sheet2!A32,MATCH('Data Dump'!B:B,'Data Dump'!B:B,0)),""),ROW('Data Dump'!$A$1:$A$2000)-ROW('Data Dump'!$A$1)+1))) -> #VALUE! | G32: Jonathan Berger | K32: =SUM(SIGN(FREQUENCY(IFERROR(IF('Data Dump'!C:C=Sheet2!G32,MATCH('Data Dump'!B:B,'Data Dump'!B:B,0)),""),ROW('Data Dump'!$A$1:$A$2000)-ROW('Data Dump'!$A$1)+1))) -> #VALUE!
A33: Open - Not Contacted | G33: Open - Not Contacted
A34: Actively Working | C34: =COUNTIFS('Data Dump'!$A:$A,Sheet2!$A$32,'Data Dump'!$F:$F,Sheet2!A34) -> 5 | D34: =ROUND((C34/$E$32),2) -> #VALUE! | E34: =C34&" / "&D34 -> #VALUE! | G34: Actively Working | I34: =COUNTIFS('Data Dump'!$A:$A,Sheet2!$A$32,'Data Dump'!$F:$F,Sheet2!G34) -> 5 | J34: =ROUND((I34/$E$32),2) -> #VALUE! | K34: =I34&" / "&J34 -> #VALUE!
A35: Nurturing | C35: =COUNTIFS('Data Dump'!$A:$A,Sheet2!$A$32,'Data Dump'!$F:$F,Sheet2!A35) -> 0 | D35: =ROUND((C35/$E$32),2) -> #VALUE! | E35: =C35&" / "&D35 -> #VALUE! | G35: Nurturing | I35: =COUNTIFS('Data Dump'!$A:$A,Sheet2!$A$32,'Data Dump'!$F:$F,Sheet2!G35) -> 0 | J35: =ROUND((I35/$E$32),2) -> #VALUE! | K35: =I35&" / "&J35 -> #VALUE!
A36: Unqualified | C36: =COUNTIFS('Data Dump'!$A:$A,Sheet2!$A$32,'Data Dump'!$F:$F,Sheet2!A36) -> 0 | D36: =ROUND((C36/$E$32),2) -> #VALUE! | E36: =C36&" / "&D36 -> #VALUE! | G36: Unqualified | I36: =COUNTIFS('Data Dump'!$A:$A,Sheet2!$A$32,'Data Dump'!$F:$F,Sheet2!G36) -> 0 | J36: =ROUND((I36/$E$32),2) -> #VALUE! | K36: =I36&" / "&J36 -> #VALUE!
A37: Retail - Small Box | E37: =SUM(SIGN(FREQUENCY(IFERROR(IF('Data Dump'!A:A=Sheet2!A37,MATCH('Data Dump'!B:B,'Data Dump'!B:B,0)),""),ROW('Data Dump'!$A$1:$A$2000)-ROW('Data Dump'!$A$1)+1))) -> #VALUE! | G37: John Richmond | K37: =SUM(SIGN(FREQUENCY(IFERROR(IF('Data Dump'!C:C=Sheet2!G37,MATCH('Data Dump'!B:B,'Data Dump'!B:B,0)),""),ROW('Data Dump'!$A$1:$A$2000)-ROW('Data Dump'!$A$1)+1))) -> #VALUE!
A38: Open - Not Contacted | G38: Open - Not Contacted
A39: Actively Working | C39: =COUNTIFS('Data Dump'!$A:$A,Sheet2!$A$37,'Data Dump'!$F:$F,Sheet2!A39) -> 53 | D39: =ROUND((C39/$E$37),2) -> #VALUE! | E39: =C39&" / "&D39 -> #VALUE! | G39: Actively Working | I39: =COUNTIFS('Data Dump'!$A:$A,Sheet2!$A$37,'Data Dump'!$F:$F,Sheet2!G39) -> 53 | J39: =ROUND((I39/$E$37),2) -> #VALUE! | K39: =I39&" / "&J39 -> #VALUE!
A40: Nurturing | C40: =COUNTIFS('Data Dump'!$A:$A,Sheet2!$A$37,'Data Dump'!$F:$F,Sheet2!A40) -> 2 | D40: =ROUND((C40/$E$37),2) -> #VALUE! | E40: =C40&" / "&D40 -> #VALUE! | G40: Nurturing | I40: =COUNTIFS('Data Dump'!$A:$A,Sheet2!$A$37,'Data Dump'!$F:$F,Sheet2!G40) -> 2 | J40: =ROUND((I40/$E$37),2) -> #VALUE! | K40: =I40&" / "&J40 -> #VALUE!
...

Sheet Data Dump
A1: Vertical | B1: Company / Account | C1: Lead Owner | D1: First Name | E1: Last Name | F1: Lead Status | G1: Title | H1: Lead Source | I1: Lead ID
A2: Convenience Stores / Gas Stations | B2: Sunoco | C2: Michael Donohue | D2: Lynn | E2: Elsenhans | F2: Open - Not Contacted | G2: Chairman of the Board, President, Chief Executive Officer | H2: Cold Call - Internal | I2: 00QF000000LoBOk
A3: Convenience Stores / Gas Stations | B3: Sunoco | C3: Michael Donohue | D3: Greg | E3: Gombar | F3: Open - Not Contacted | G3: Chief Financial Officer | H3: Cold Call - Internal | I3: 00QF000000LoBOl
A4: Convenience Stores / Gas Stations | B4: Sunoco | C4: Michael Donohue | D4: Thomas | E4: Hoffman | F4: Open - Not Contacted | G4: Senior Vice President & Chief Financial Officer | H4: Cold Call - Internal | I4: 00QF000000LoBOm
A5: Convenience Stores / Gas Stations | B5: Sunoco | C5: Michael Donohue | D5: Joel | E5: Kriener | F5: Open - Not Contacted | G5: Information Technology Corporate Executives Chief Financial Officer, Chief Techn | H5: Cold Call - Internal | I5: 00QF000000LoBOn
A6: Convenience Stores / Gas Stations | B6: Sunoco | C6: Michael Donohue | D6: Neal | E6: Murphy | F6: Open - Not Contacted | G6: Chief Financial Officer | H6: Cold Call - Internal | I6: 00QF000000LoBOo
A7: Convenience Stores / Gas Stations | B7: Sunoco | C7: Michael Donohue | D7: Michael | E7: Thomson | F7: Open - Not Contacted | G7: Senior Vice President, Sunoco, Inc.; President, SunCoke Energy, Inc. | H7: Cold Call - Internal | I7: 00QF000000LoBOp
A8: Convenience Stores / Gas Stations | B8: Sunoco | C8: Michael Donohue | D8: Peter | E8: Whatnell | F8: Open - Not Contacted | G8: CIO | H8: Cold Call - Internal | I8: 00QF000000LoBOq
A9: Convenience Stores / Gas Stations | B9: 7-Eleven | C9: Matt Creager | D9: Dan | E9: Gilligan | F9: Actively Working | G9: Manager, Energy | H9: Cold Call - Internal | I9: 00QF000000LoBLM
A10: Convenience Stores / Gas Stations | B10: Alimentation Couche-Tard (Circle K) | C10: Matt Creager | D10: Craig | E10: Boswell | F10: Actively Working | G10: Director, Facilities | H10: Cold Call - Internal | I10: 00QF000000LoykA
A11: Convenience Stores / Gas Stations | B11: Alimentation Couche-Tard (Circle K) | C11: Matt Creager | D11: Keith | E11: Coffman | F11: Actively Working | G11: Facilities Supervisor, Oklahoma | H11: Cold Call - Internal | I11: 00QF000000LoykB
A12: Convenience Stores / Gas Stations | B12: Sheetz | C12: Matt Creager | D12: Doug | E12: Knisely | F12: Open - Not Contacted | G12: Manager of Petroleum and Building Construction | H12: Trade Show | I12: 00QA0000007XqGK
... A24: Convenience Stores / Gas Stations | B24: Delek Holdings (MAPCO) | C24: Matt Creager | D24: Roger | E24: Parton | F24: Open - Not Contacted | G24: Senior Manager, Maintenance | H24: Trade Show | I24: 00QF000000LnAGq
A25: Convenience Stores / Gas Stations | B25: Marathon Oil (Speedway SuperAmerica) | C25: Matt Creager | D25: Troy | E25: Oliver | F25: Open - Not Contacted | H25: Trade Show | I25: 00QF000000LnAGr
A26: Convenience Stores / Gas Stations | B26: Alimentation Couche-Tard (Circle K) | C26: Matt Creager | D26: Mike | E26: O`Sullivan | F26: Unqualified | G26: Director, Facilities | H26: Trade Show | I26: 00QF000000LnAGt
A27: Convenience Stores / Gas Stations | B27: United Dairy Farmers | C27: Matt Creager | D27: Darryl | E27: Neltner | F27: Open - Not Contacted | G27: Controller | H27: Trade Show | I27: 00QF000000LnAGu
A28: Convenience Stores / Gas Stations | B28: Maverik Country Stores | C28: Matt Creager | D28: Dan | E28: Murry | F28: Open - Not Contacted | G28: Director of Store Development | H28: Cold Call - Internal | I28: 00QF000000LnAGv
A29: Convenience Stores / Gas Stations | B29: Tedeschi Food Shops | C29: Matt Creager | D29: Bob | E29: McGann | F29: Open - Not Contacted | G29: Vice President Store Development | H29: Trade Show | I29: 00QF000000LnAGz
A30: Convenience Stores / Gas Stations | B30: Carey Johnson Oil (EZ Go Food Store) | C30: Matt Creager | D30: Twyla | E30: McDonald | F30: Unqualified | G30: Controller | H30: Cold Call - Internal | I30: 00QF000000LnAH0
A31: Convenience Stores / Gas Stations | B31: Royal Farms | C31: Matt Creager | D31: Joe | E31: Lynch | F31: Open - Not Contacted | G31: District Manager | H31: Cold Call - Internal | I31: 00QF000000LnAH3
A32: Convenience Stores / Gas Stations | B32: Southwest Convenience Stores (Alon USA) | C32: Matt Creager | D32: Jonathan | E32: Ketchum | F32: Open - Not Contacted | G32: Vice President Operations | H32: Trade Show | I32: 00QF000000LnAH8
A33: Convenience Stores / Gas Stations | B33: Kwik Stop | C33: Matt Creager | D33: Jim | E33: Kahok | F33: Open - Not Contacted | G33: Controller | H33: Trade Show | I33: 00QF000000LnAHA
A34: Convenience Stores / Gas Stations | B34: Hess | C34: Matt Creager | D34: George | E34: Houk | F34: Open - Not Contacted | G34: Director of Pre-Construction Services | H34: Cold Call - Internal | I34: 00QF000000LnAHH
A35: Convenience Stores / Gas Stations | B35: Alliance Energy | C35: Matt Creager | D35: Jaime | E35: Cook | F35: Actively Working | G35: Facilities Director | H35: Cold Call - Internal | I35: 00QF000000Loy7E
A36: Convenience Stores / Gas Stations | B36: Jacksons Food Stores | C36: Matt Creager | D36: Randy | E36: Helfer | F36: Open - Not Contacted | G36: Facility Director | H36: Cold Call - Internal | I36: 00QF000000LnAHM
A37: Convenience Stores / Gas Stations | B37: Go-Mart | C37: Matt Creager | D37: John | E37: Heater | F37: Open - Not Contacted | G37: President | H37: Cold Call - Internal | I37: 00QF000000LnAHN
A38: Convenience Stores / Gas Stations | B38: CEFCO Convenience Stores | C38: Matt Creager | D38: Brett | E38: Giesick | F38: Nurturing | G38: Chief Retail Officer | H38: Cold Call - Internal | I38: 00QF000000LnAHS
A39: Convenience Stores / Gas Stations | B39: Stewart's Shops | C39: Matt Creager | E39: Gatti | F39: Open - Not Contacted | H39: Cold Call - Internal | I39: 00QF000000LnAHU
A40: Convenience Stores / Gas Stations | B40: Casey's General Stores | C40: Matt Creager | D40: Robert | E40: Ford | F40: Unqualified | G40: VP Store Operations | H40: Cold Call - Internal | I40: 00QF000000LnAHX
A41: Convenience Stores / Gas Stations | B41: Holiday Companies | C41: Matt Creager | D41: Tom | E41: Fliss | F41: Open - Not Contacted | G41: Energy Manager | H41: Cold Call - Internal | I41: 00QF000000LnAHY
A42: Convenience Stores / Gas Stations | B42: Allsup's Convenience Stores | C42: Matt Creager | D42: RoGene | E42: Chaddick | F42: Actively Working | G42: Controller | H42: Cold Call - Internal | I42: 00QF000000LnAHp
A43: Convenience Stores / Gas Stations | B43: Thorntons | C43: Matt Creager | D43: Mike | E43: Deel | F43: Open - Not Contacted | G43: Director, Facilities Services | H43: Cold Call - Internal | I43: 00QF000000LnAHe
A44: Convenience Stores / Gas Stations | B44: Tesoro Petroleum | C44: Matt Creager | D44: Jennifer | E44: Cox | F44: Open - Not Contacted | G44: Project Manager, Facilities Operations | H44: Trade Show | I44: 00QF000000LnAHj
A45: Convenience Stores / Gas Stations | B45: Quick Check | C45: Matt Creager | D45: Marty | E45: Connolly | F45: Open - Not Contacted | G45: Maintenance Manager | H45: Cold Call - Internal | I45: 00QF000000LnAHl
A46: Convenience Stores / Gas Stations | B46: Swiss Farms | C46: Matt Creager | D46: Rob | E46: Coldwell | F46: Open - Not Contacted | G46: Director, Franchising | H46: Trade Show | I46: 00QF000000LnAHm
A47: Convenience Stores / Gas Stations | B47: Murphy Oil USA | C47: Matt Creager | D47: Clif | E47: Coker | F47: Open - Not Contacted | G47: Manager, Maintenance Murphy USA | H47: Cold Call - Internal | I47: 00QF000000LnAHn
A48: Convenience Stores / Gas Stations | B48: Allsup's Convenience Stores | C48: Matt Creager | D48: Brian | E48: Ashburn | F48: Actively Working | G48: COO | H48: Cold Call - Internal | I48: 00QF000000LoBFF
A49: Convenience Stores / Gas Stations | B49: MFA Oil Company - Break Time | C49: Matt Creager | D49: Ken | E49: Caspell | F49: Open - Not Contacted | G49: Consultant Acquisitions, Development | H49: Trade Show | I49: 00QF000000LnAHr
A50: Convenience Stores / Gas Stations | B50: Alimentation Couche-Tard (Circle K) | C50: Matt Creager | D50: Ed | E50: Carver | F50: Unqualified | G50: Director, Facilities and Construction | H50: Trade Show | I50: 00QF000000LnAHs
A51: Convenience Stores / Gas Stations | B51: Western Refining | C51: Matt Creager | D51: Roger | E51: Burton | F51: Open - Not Contacted | G51: Director, Retail Properties and Facilities Management | H51: Trade Show | I51: 00QF000000LnAHx
...

Sheet Sheet1
A1: Vertical | B1: Company / Account | C1: Lead Owner | D1: First Name | E1: Last Name | F1: Lead Status | G1: Title | H1: Lead Source | I1: Lead ID
A2: Restaurants - Full Serve / Casual Dining | B2: Darden Restaurants | C2: Michael Donohue | D2: Stephen | E2: Judge | F2: Unqualified | G2: Chief Executive Officer | H2: Cold Call - Internal | I2: 00QF000000LoBO3 | K2: Restaurants - Full Serve / Casual Dining | L2: =COUNTIF(A:A,"Restaurants - Full Serve / Casual Dining") -> 5 | M2: =COUNTIF(A:A,K2) -> 5
A3: Restaurants - Full Serve / Casual Dining | B3: McDs | C3: Michael Donohue | D3: Andrew | E3: Madsen | F3: Unqualified | G3: President, Chief Operating Officer, Director | H3: Cold Call - Internal | I3: 00QF000000LoBO4 | K3: Open - Not Contacted | L3: =COUNTIFS($A:$A,$K$2,$F:$F,K3) -> 2
A4: Restaurants - Full Serve / Casual Dining | B4: Blah Blah | C4: Michael Donohue | D4: Clarence | E4: Odis | F4: Unqualified | G4: Chief Financial Officer | H4: Cold Call - Internal | I4: 00QF000000LoBO5 | K4: Unqualified | L4: =COUNTIFS($A:$A,$K$2,$F:$F,K4) -> 3
A5: Restaurants - Full Serve / Casual Dining | B5: Ho ho | C5: Michael Donohue | D5: Ian | E5: Olson | F5: Open - Not Contacted | G5: Director Sustainability | H5: Cold Call - Internal | I5: 00QF000000LoBO6
A6: Restaurants - Full Serve / Casual Dining | B6: Darden Restaurants | C6: Michael Donohue | D6: Brad | E6: Richmond | F6: Open - Not Contacted | G6: Senior Vice President and Chief Financial Officer | H6: Cold Call - Internal | I6: 00QF000000LoBO8
A7: Retail - Grocery | B7: Delhaize America | C7: Michael Donohue | D7: Richard | E7: Anicetti | F7: Open - Not Contacted | G7: Chief Executive Officer of Food Lion, President of Food Lion and Chief Operating | H7: Cold Call - Internal | I7: 00QF000000LoBOA | K7: Retail - Grocery | L7: =COUNTIF(A:A,"Retail - Grocery") -> 3 | M7: =COUNTIF(A:A,K7) -> 3
A8: Retail - Grocery | B8: Delhaize America | C8: Michael Donohue | D8: Michael | E8: Byars | F8: Open - Not Contacted | G8: Chief Operating Officer of Kash N Karry | H8: Cold Call - Internal | I8: 00QF000000LoBOB
A9: Retail - Grocery | B9: Delhaize America | C9: Michael Donohue | D9: Paul | E9: Fritzson | F9: Open - Not Contacted | G9: Chief Financial Officer of Hannaford Bros and Executive Vice President of Hannaf | H9: Cold Call - Internal | I9: 00QF000000LoBOC
F14: =SUMPRODUCT((B:B<>"")/COUNTIF(A:A,K2)) -> 1.8
C15: =IF(A:A="Restaurants - Full Serve / Casual Dining",SUMPRODUCT((B:B<>"")/COUNTIF(B:B,B:B&"")),1) -> 1 | E15: =SUM(SIGN(FREQUENCY(IFERROR(IF(A:A="restaurants - Full serve / casual dining",MATCH(B:B,B:B,0)),""),ROW(A:A)-ROW(A)+1))) -> #VALUE!
E17: {=SUM(SIGN(FREQUENCY(IFERROR(IF(A1:A1000=K2,MATCH(B1:B1000,B1:B1000,0)),""),ROW(A1:A1000)-ROW(A)+1)))} -> #N/A | F17: {=SUM(SIGN(FREQUENCY(IFERROR(IF(A1:A17=K2,MATCH(B1:B17,B1:B17,0)),""),ROW(A1:A17)-ROW(A1)+1)))} -> 4

Sheet Visual
A1: TOTAL # OF COMPANIES | B1: =SUMPRODUCT(('Data Dump'!B:B<>"")/COUNTIF('Data Dump'!B:B,'Data Dump'!B:B&"")) -> 488
B3: Total Prospect Companies | C3: Open - Not Contacted | D3: % of Total Vertical Open - Not Contacted | E3: Actively Working | F3: % of Total Vertical Actively Working | G3: Nurturing | H3: % of Total Vertical Nurturing | I3: Unqualified | J3: % of Total Vertical Unqualified
A4: Convenience Stores / Gas Stations | B4: {=SUM(SIGN(FREQUENCY(IFERROR(IF('Data Dump'!$A:$A=A4,MATCH('Data Dump'!$B:$B,'Data Dump'!$B:$B,0)),""),ROW('Data Dump'!$A$1:$A$2000)-ROW('Data Dump'!$A$1)+1)))} -> 45 | D4: =C4/B4 -> 0 | F4: =E4/B4 -> 0 | H4: =G4/B4 -> 0 | J4: =I4/B4 -> 0
A5: Restaurants - Full Serve / Casual Dining | B5: {=SUM(SIGN(FREQUENCY(IFERROR(IF('Data Dump'!$A:$A=A5,MATCH('Data Dump'!$B:$B,'Data Dump'!$B:$B,0)),""),ROW('Data Dump'!$A$1:$A$2000)-ROW('Data Dump'!$A$1)+1)))} -> 66 | D5: =C5/B5 -> 0 | F5: =E5/B5 -> 0 | H5: =G5/B5 -> 0 | J5: =I5/B5 -> 0
A6: Restaurants - Quick Serve / Fast Food | B6: {=SUM(SIGN(FREQUENCY(IFERROR(IF('Data Dump'!$A:$A=A6,MATCH('Data Dump'!$B:$B,'Data Dump'!$B:$B,0)),""),ROW('Data Dump'!$A$1:$A$2000)-ROW('Data Dump'!$A$1)+1)))} -> 81 | D6: =C6/B6 -> 0 | F6: =E6/B6 -> 0 | H6: =G6/B6 -> 0 | J6: =I6/B6 -> 0
A7: Retail - Big Box | B7: {=SUM(SIGN(FREQUENCY(IFERROR(IF('Data Dump'!$A:$A=A7,MATCH('Data Dump'!$B:$B,'Data Dump'!$B:$B,0)),""),ROW('Data Dump'!$A$1:$A$2000)-ROW('Data Dump'!$A$1)+1)))} -> 54 | D7: =C7/B7 -> 0 | F7: =E7/B7 -> 0 | H7: =G7/B7 -> 0 | J7: =I7/B7 -> 0
A8: Retail - Grocery | B8: {=SUM(SIGN(FREQUENCY(IFERROR(IF('Data Dump'!$A:$A=A8,MATCH('Data Dump'!$B:$B,'Data Dump'!$B:$B,0)),""),ROW('Data Dump'!$A$1:$A$2000)-ROW('Data Dump'!$A$1)+1)))} -> 95 | D8: =C8/B8 -> 0 | F8: =E8/B8 -> 0 | H8: =G8/B8 -> 0 | J8: =I8/B8 -> 0
A9: Retail - Medium Box | B9: {=SUM(SIGN(FREQUENCY(IFERROR(IF('Data Dump'!$A:$A=A9,MATCH('Data Dump'!$B:$B,'Data Dump'!$B:$B,0)),""),ROW('Data Dump'!$A$1:$A$2000)-ROW('Data Dump'!$A$1)+1)))} -> 47 | D9: =C9/B9 -> 0 | F9: =E9/B9 -> 0 | H9: =G9/B9 -> 0 | J9: =I9/B9 -> 0
A10: Retail - Pharmacy | B10: {=SUM(SIGN(FREQUENCY(IFERROR(IF('Data Dump'!$A:$A=A10,MATCH('Data Dump'!$B:$B,'Data Dump'!$B:$B,0)),""),ROW('Data Dump'!$A$1:$A$2000)-ROW('Data Dump'!$A$1)+1)))} -> 7 | D10: =C10/B10 -> 0 | F10: =E10/B10 -> 0 | H10: =G10/B10 -> 0 | J10: =I10/B10 -> 0
A11: Retail - Small Box | B11: {=SUM(SIGN(FREQUENCY(IFERROR(IF('Data Dump'!$A:$A=A11,MATCH('Data Dump'!$B:$B,'Data Dump'!$B:$B,0)),""),ROW('Data Dump'!$A$1:$A$2000)-ROW('Data Dump'!$A$1)+1)))} -> 99 | D11: =C11/B11 -> 0 | F11: =E11/B11 -> 0 | H11: =G11/B11 -> 0 | J11: =I11/B11 -> 0
B13: Total Prospect Companies | C13: Open - Not Contacted | D13: % of Total Vertical Open - Not Contacted | E13: Actively Working | F13: % of Total Vertical Actively Working | G13: Nurturing | H13: % of Total Vertical Nurturing | I13: Unqualified | J13: % of Total Vertical Unqualified
A14: Allen Scott | B14: {=SUM(SIGN(FREQUENCY(IFERROR(IF('Data Dump'!$C:$C=A14,MATCH('Data Dump'!$B:$B,'Data Dump'!$B:$B,0)),""),ROW('Data Dump'!$A$1:$A$2000)-ROW('Data Dump'!$A$1)+1)))} -> 3 | D14: =C14/B14 -> 0 | F14: =E14/B14 -> 0 | H14: =G14/B14 -> 0 | J14: =I14/B14 -> 0
A15: John Richmond | B15: {=SUM(SIGN(FREQUENCY(IFERROR(IF('Data Dump'!$C:$C=A15,MATCH('Data Dump'!$B:$B,'Data Dump'!$B:$B,0)),""),ROW('Data Dump'!$A$1:$A$2000)-ROW('Data Dump'!$A$1)+1)))} -> 87 | D15: =C15/B15 -> 0 | F15: =E15/B15 -> 0 | H15: =G15/B15 -> 0 | J15: =I15/B15 -> 0
A16: Jonathan Berger | B16: {=SUM(SIGN(FREQUENCY(IFERROR(IF('Data Dump'!$C:$C=A16,MATCH('Data Dump'!$B:$B,'Data Dump'!$B:$B,0)),""),ROW('Data Dump'!$A$1:$A$2000)-ROW('Data Dump'!$A$1)+1)))} -> 134 | D16: =C16/B16 -> 0 | F16: =E16/B16 -> 0 | H16: =G16/B16 -> 0 | J16: =I16/B16 -> 0
A17: Matt Creager | B17: {=SUM(SIGN(FREQUENCY(IFERROR(IF('Data Dump'!$C:$C=A17,MATCH('Data Dump'!$B:$B,'Data Dump'!$B:$B,0)),""),ROW('Data Dump'!$A$1:$A$2000)-ROW('Data Dump'!$A$1)+1)))} -> 72 | D17: =C17/B17 -> 0 | F17: =E17/B17 -> 0 | H17: =G17/B17 -> 0 | J17: =I17/B17 -> 0
A18: Michael Donohue | B18: {=SUM(SIGN(FREQUENCY(IFERROR(IF('Data Dump'!$C:$C=A18,MATCH('Data Dump'!$B:$B,'Data Dump'!$B:$B,0)),""),ROW('Data Dump'!$A$1:$A$2000)-ROW('Data Dump'!$A$1)+1)))} -> 17 | D18: =C18/B18 -> 0 | F18: =E18/B18 -> 0 | H18: =G18/B18 -> 0 | J18: =I18/B18 -> 0
A19: Mike Pluff | B19: {=SUM(SIGN(FREQUENCY(IFERROR(IF('Data Dump'!$C:$C=A19,MATCH('Data Dump'!$B:$B,'Data Dump'!$B:$B,0)),""),ROW('Data Dump'!$A$1:$A$2000)-ROW('Data Dump'!$A$1)+1)))} -> 107 | D19: =C19/B19 -> 0 | F19: =E19/B19 -> 0 | H19: =G19/B19 -> 0 | J19: =I19/B19 -> 0
A20: Steven Shartzer | B20: {=SUM(SIGN(FREQUENCY(IFERROR(IF('Data Dump'!$C:$C=A20,MATCH('Data Dump'!$B:$B,'Data Dump'!$B:$B,0)),""),ROW('Data Dump'!$A$1:$A$2000)-ROW('Data Dump'!$A$1)+1)))} -> 58 | D20: =C20/B20 -> 0 | F20: =E20/B20 -> 0 | H20: =G20/B20 -> 0 | J20: =I20/B20 -> 0
A21: Robert Giblett | B21: {=SUM(SIGN(FREQUENCY(IFERROR(IF('Data Dump'!$C:$C=A21,MATCH('Data Dump'!$B:$B,'Data Dump'!$B:$B,0)),""),ROW('Data Dump'!$A$1:$A$2000)-ROW('Data Dump'!$A$1)+1)))} -> 25 | D21: =C21/B21 -> 0 | F21: =E21/B21 -> 0 | H21: =G21/B21 -> 0 | J21: =I21/B21 -> 0
B23: Total Prospect Companies | C23: Allen Scott | D23: % | E23: John Richmond | F23: % | G23: Jonathan Berger | H23: % | I23: Matt Creager | J23: % | K23: Michael Donohue | L23: % | M23: Mike Pluff | N23: % | O23: Steven Startzer | P23: % | Q23: Rober Giblett | R23: %
A24: Convenience Stores / Gas Stations | B24: {=SUM(SIGN(FREQUENCY(IFERROR(IF('Data Dump'!$A:$A=A24,MATCH('Data Dump'!$B:$B,'Data Dump'!$B:$B,0)),""),ROW('Data Dump'!$A$1:$A$2000)-ROW('Data Dump'!$A$1)+1)))} -> 45 | D24: =C24/B24 -> 0 | F24: =E24/B24 -> 0 | H24: =G24/B24 -> 0 | J24: =I24/B24 -> 0 | L24: =K24/B24 -> 0 | N24: =M24/B24 -> 0 | P24: =O24/B24 -> 0 | R24: =Q24/B24 -> 0
A25: Restaurants - Full Serve / Casual Dining | B25: {=SUM(SIGN(FREQUENCY(IFERROR(IF('Data Dump'!$A:$A=A25,MATCH('Data Dump'!$B:$B,'Data Dump'!$B:$B,0)),""),ROW('Data Dump'!$A$1:$A$2000)-ROW('Data Dump'!$A$1)+1)))} -> 66 | D25: =C25/B25 -> 0 | F25: =E25/B25 -> 0 | H25: =G25/B25 -> 0 | J25: =I25/B25 -> 0 | L25: =K25/B25 -> 0 | N25: =M25/B25 -> 0 | P25: =O25/B25 -> 0 | R25: =Q25/B25 -> 0
A26: Restaurants - Quick Serve / Fast Food | B26: {=SUM(SIGN(FREQUENCY(IFERROR(IF('Data Dump'!$A:$A=A26,MATCH('Data Dump'!$B:$B,'Data Dump'!$B:$B,0)),""),ROW('Data Dump'!$A$1:$A$2000)-ROW('Data Dump'!$A$1)+1)))} -> 81 | D26: =C26/B26 -> 0 | F26: =E26/B26 -> 0 | H26: =G26/B26 -> 0 | J26: =I26/B26 -> 0 | L26: =K26/B26 -> 0 | N26: =M26/B26 -> 0 | P26: =O26/B26 -> 0 | R26: =Q26/B26 -> 0
A27: Retail - Big Box | B27: {=SUM(SIGN(FREQUENCY(IFERROR(IF('Data Dump'!$A:$A=A27,MATCH('Data Dump'!$B:$B,'Data Dump'!$B:$B,0)),""),ROW('Data Dump'!$A$1:$A$2000)-ROW('Data Dump'!$A$1)+1)))} -> 54 | D27: =C27/B27 -> 0 | F27: =E27/B27 -> 0 | H27: =G27/B27 -> 0 | J27: =I27/B27 -> 0 | L27: =K27/B27 -> 0 | N27: =M27/B27 -> 0 | P27: =O27/B27 -> 0 | R27: =Q27/B27 -> 0
A28: Retail - Grocery | B28: {=SUM(SIGN(FREQUENCY(IFERROR(IF('Data Dump'!$A:$A=A28,MATCH('Data Dump'!$B:$B,'Data Dump'!$B:$B,0)),""),ROW('Data Dump'!$A$1:$A$2000)-ROW('Data Dump'!$A$1)+1)))} -> 95 | D28: =C28/B28 -> 0 | F28: =E28/B28 -> 0 | H28: =G28/B28 -> 0 | J28: =I28/B28 -> 0 | L28: =K28/B28 -> 0 | N28: =M28/B28 -> 0 | P28: =O28/B28 -> 0 | R28: =Q28/B28 -> 0
A29: Retail - Medium Box | B29: {=SUM(SIGN(FREQUENCY(IFERROR(IF('Data Dump'!$A:$A=A29,MATCH('Data Dump'!$B:$B,'Data Dump'!$B:$B,0)),""),ROW('Data Dump'!$A$1:$A$2000)-ROW('Data Dump'!$A$1)+1)))} -> 47 | D29: =C29/B29 -> 0 | F29: =E29/B29 -> 0 | H29: =G29/B29 -> 0 | J29: =I29/B29 -> 0 | L29: =K29/B29 -> 0 | N29: =M29/B29 -> 0 | P29: =O29/B29 -> 0 | R29: =Q29/B29 -> 0
A30: Retail - Pharmacy | B30: {=SUM(SIGN(FREQUENCY(IFERROR(IF('Data Dump'!$A:$A=A30,MATCH('Data Dump'!$B:$B,'Data Dump'!$B:$B,0)),""),ROW('Data Dump'!$A$1:$A$2000)-ROW('Data Dump'!$A$1)+1)))} -> 7 | D30: =C30/B30 -> 0 | F30: =E30/B30 -> 0 | H30: =G30/B30 -> 0 | J30: =I30/B30 -> 0 | L30: =K30/B30 -> 0 | N30: =M30/B30 -> 0 | P30: =O30/B30 -> 0 | R30: =Q30/B30 -> 0
A31: Retail - Small Box | B31: {=SUM(SIGN(FREQUENCY(IFERROR(IF('Data Dump'!$A:$A=A31,MATCH('Data Dump'!$B:$B,'Data Dump'!$B:$B,0)),""),ROW('Data Dump'!$A$1:$A$2000)-ROW('Data Dump'!$A$1)+1)))} -> 99 | D31: =C31/B31 -> 0 | F31: =E31/B31 -> 0 | H31: =G31/B31 -> 0 | J31: =I31/B31 -> 0 | L31: =K31/B31 -> 0 | N31: =M31/B31 -> 0 | P31: =O31/B31 -> 0 | R31: =Q31/B31 -> 0

Sheet Sheet3
A1: Unique Vertical | B1: Total Unique Co. Count | C1: Count of Lead Status
C2: {=IFERROR(INDEX(Table2[Lead Status],MATCH(1,IF(Table2[Lead Status]<>"",IF(ISNA(MATCH(Table2[Lead Status],$A2:A2,0)),1)),0)),"")} -> Open - Not Contacted | D2: % of Total | E2: {=IFERROR(INDEX(Table2[Lead Status],MATCH(1,IF(Table2[Lead Status]<>"",IF(ISNA(MATCH(Table2[Lead Status],$A2:C2,0)),1)),0)),"")} -> Actively Working | F2: % of Total | G2: {=IFERROR(INDEX(Table2[Lead Status],MATCH(1,IF(Table2[Lead Status]<>"",IF(ISNA(MATCH(Table2[Lead Status],$A2:E2,0)),1)),0)),"")} -> Unqualified | H2: % of Total | I2: {=IFERROR(INDEX(Table2[Lead Status],MATCH(1,IF(Table2[Lead Status]<>"",IF(ISNA(MATCH(Table2[Lead Status],$A2:G2,0)),1)),0)),"")} -> Nurturing | J2: % of Total | K2: {=IFERROR(INDEX(Table2[Lead Status],MATCH(1,IF(Table2[Lead Status]<>"",IF(ISNA(MATCH(Table2[Lead Status],$A2:J2,0)),1)),0)),"")}
A3: {=IFERROR(INDEX(Table2[Vertical],MATCH(1,IF(Table2[Vertical]<>"",IF(ISNA(MATCH(Table2[Vertical],A$1:A2,0)),1)),0)),"")} -> Convenience Stores / Gas Stations | B3: {=IF(A3="","",SUM(IF(FREQUENCY(IFERROR(IF(Table2[Vertical]=A3,MATCH(Table2[Company / Account],Table2[Company / Account],0)),""),ROW(Table2[Vertical])-ROW(Table2[#Headers])),1)))} -> 45 | C3: {=IF(OR(C$2="",$A3=""),"",SUM(IF(FREQUENCY(IFERROR(IF(Table2[Vertical]=$A3,IF(Table2[Lead Status]=C$2,MATCH(Table2[Company / Account],Table2[Company / Account],0))),""),ROW(Table2[Vertical])-ROW(Table2[#Headers])),1)))} -> 34 | D3: =C3/B3 -> 0.75555556 | E3: {=IF(OR(E$2="",$A3=""),"",SUM(IF(FREQUENCY(IFERROR(IF(Table2[Vertical]=$A3,IF(Table2[Lead Status]=E$2,MATCH(Table2[Company / Account],Table2[Company / Account],0))),""),ROW(Table2[Vertical])-ROW(Table2[#Headers])),1)))} -> 17 | F3: =E3/B3 -> 0.37777778 | G3: {=IF(OR(G$2="",$A3=""),"",SUM(IF(FREQUENCY(IFERROR(IF(Table2[Vertical]=$A3,IF(Table2[Lead Status]=G$2,MATCH(Table2[Company / Account],Table2[Company / Account],0))),""),ROW(Table2[Vertical])-ROW(Table2[#Headers])),1)))} -> 6 | H3: =G3/B3 -> 0.13333333 | I3: {=IF(OR(I$2="",$A3=""),"",SUM(IF(FREQUENCY(IFERROR(IF(Table2[Vertical]=$A3,IF(Table2[Lead Status]=I$2,MATCH(Table2[Company / Account],Table2[Company / Account],0))),""),ROW(Table2[Vertical])-ROW(Table2[#Headers])),1)))} -> 6 | J3: =I3/B3 -> 0.13333333 | K3: {=IF(OR(K$2="",$A3=""),"",SUM(IF(FREQUENCY(IFERROR(IF(Table2[Vertical]=$A3,IF(Table2[Lead Status]=K$2,MATCH(Table2[Company / Account],Table2[Company / Account],0))),""),ROW(Table2[Vertical])-ROW(Table2[#Headers])),1)))}
A4: {=IFERROR(INDEX(Table2[Vertical],MATCH(1,IF(Table2[Vertical]<>"",IF(ISNA(MATCH(Table2[Vertical],A$1:A3,0)),1)),0)),"")} -> Restaurants - Full Serve / Casual Dining | B4: {=IF(A4="","",SUM(IF(FREQUENCY(IFERROR(IF(Table2[Vertical]=A4,MATCH(Table2[Company / Account],Table2[Company / Account],0)),""),ROW(Table2[Vertical])-ROW(Table2[#Headers])),1)))} -> 66 | C4: {=IF(OR(C$2="",$A4=""),"",SUM(IF(FREQUENCY(IFERROR(IF(Table2[Vertical]=$A4,IF(Table2[Lead Status]=C$2,MATCH(Table2[Company / Account],Table2[Company / Account],0))),""),ROW(Table2[Vertical])-ROW(Table2[#Headers])),1)))} -> 48 | D4: =C4/B4 -> 0.72727273 | E4: {=IF(OR(E$2="",$A4=""),"",SUM(IF(FREQUENCY(IFERROR(IF(Table2[Vertical]=$A4,IF(Table2[Lead Status]=E$2,MATCH(Table2[Company / Account],Table2[Company / Account],0))),""),ROW(Table2[Vertical])-ROW(Table2[#Headers])),1)))} -> 16 | F4: =E4/B4 -> 0.24242424 | G4: {=IF(OR(G$2="",$A4=""),"",SUM(IF(FREQUENCY(IFERROR(IF(Table2[Vertical]=$A4,IF(Table2[Lead Status]=G$2,MATCH(Table2[Company / Account],Table2[Company / Account],0))),""),ROW(Table2[Vertical])-ROW(Table2[#Headers])),1)))} -> 5 | H4: =G4/B4 -> 0.075757576 | I4: {=IF(OR(I$2="",$A4=""),"",SUM(IF(FREQUENCY(IFERROR(IF(Table2[Vertical]=$A4,IF(Table2[Lead Status]=I$2,MATCH(Table2[Company / Account],Table2[Company / Account],0))),""),ROW(Table2[Vertical])-ROW(Table2[#Headers])),1)))} -> 3 | J4: =I4/B4 -> 0.045454545 | K4: {=IF(OR(K$2="",$A4=""),"",SUM(IF(FREQUENCY(IFERROR(IF(Table2[Vertical]=$A4,IF(Table2[Lead Status]=K$2,MATCH(Table2[Company / Account],Table2[Company / Account],0))),""),ROW(Table2[Vertical])-ROW(Table2[#Headers])),1)))}
A5: {=IFERROR(INDEX(Table2[Vertical],MATCH(1,IF(Table2[Vertical]<>"",IF(ISNA(MATCH(Table2[Vertical],A$1:A4,0)),1)),0)),"")} -> Restaurants - Quick Serve / Fast Food | B5: {=IF(A5="","",SUM(IF(FREQUENCY(IFERROR(IF(Table2[Vertical]=A5,MATCH(Table2[Company / Account],Table2[Company / Account],0)),""),ROW(Table2[Vertical])-ROW(Table2[#Headers])),1)))} -> 81 | C5: {=IF(OR(C$2="",$A5=""),"",SUM(IF(FREQUENCY(IFERROR(IF(Table2[Vertical]=$A5,IF(Table2[Lead Status]=C$2,MATCH(Table2[Company / Account],Table2[Company / Account],0))),""),ROW(Table2[Vertical])-ROW(Table2[#Headers])),1)))} -> 67 | D5: =C5/B5 -> 0.82716049 | E5: {=IF(OR(E$2="",$A5=""),"",SUM(IF(FREQUENCY(IFERROR(IF(Table2[Vertical]=$A5,IF(Table2[Lead Status]=E$2,MATCH(Table2[Company / Account],Table2[Company / Account],0))),""),ROW(Table2[Vertical])-ROW(Table2[#Headers])),1)))} -> 18 | F5: =E5/B5 -> 0.22222222 | G5: {=IF(OR(G$2="",$A5=""),"",SUM(IF(FREQUENCY(IFERROR(IF(Table2[Vertical]=$A5,IF(Table2[Lead Status]=G$2,MATCH(Table2[Company / Account],Table2[Company / Account],0))),""),ROW(Table2[Vertical])-ROW(Table2[#Headers])),1)))} -> 2 | H5: =G5/B5 -> 0.024691358 | I5: {=IF(OR(I$2="",$A5=""),"",SUM(IF(FREQUENCY(IFERROR(IF(Table2[Vertical]=$A5,IF(Table2[Lead Status]=I$2,MATCH(Table2[Company / Account],Table2[Company / Account],0))),""),ROW(Table2[Vertical])-ROW(Table2[#Headers])),1)))} -> 1 | J5: =I5/B5 -> 0.012345679 | K5: {=IF(OR(K$2="",$A5=""),"",SUM(IF(FREQUENCY(IFERROR(IF(Table2[Vertical]=$A5,IF(Table2[Lead Status]=K$2,MATCH(Table2[Company / Account],Table2[Company / Account],0))),""),ROW(Table2[Vertical])-ROW(Table2[#Headers])),1)))}
A6: {=IFERROR(INDEX(Table2[Vertical],MATCH(1,IF(Table2[Vertical]<>"",IF(ISNA(MATCH(Table2[Vertical],A$1:A5,0)),1)),0)),"")} -> Retail - Big Box | B6: {=IF(A6="","",SUM(IF(FREQUENCY(IFERROR(IF(Table2[Vertical]=A6,MATCH(Table2[Company / Account],Table2[Company / Account],0)),""),ROW(Table2[Vertical])-ROW(Table2[#Headers])),1)))} -> 54 | C6: {=IF(OR(C$2="",$A6=""),"",SUM(IF(FREQUENCY(IFERROR(IF(Table2[Vertical]=$A6,IF(Table2[Lead Status]=C$2,MATCH(Table2[Company / Account],Table2[Company / Account],0))),""),ROW(Table2[Vertical])-ROW(Table2[#Headers])),1)))} -> 39 | D6: =C6/B6 -> 0.72222222 | E6: {=IF(OR(E$2="",$A6=""),"",SUM(IF(FREQUENCY(IFERROR(IF(Table2[Vertical]=$A6,IF(Table2[Lead Status]=E$2,MATCH(Table2[Company / Account],Table2[Company / Account],0))),""),ROW(Table2[Vertical])-ROW(Table2[#Headers])),1)))} -> 26 | F6: =E6/B6 -> 0.48148148 | G6: {=IF(OR(G$2="",$A6=""),"",SUM(IF(FREQUENCY(IFERROR(IF(Table2[Vertical]=$A6,IF(Table2[Lead Status]=G$2,MATCH(Table2[Company / Account],Table2[Company / Account],0))),""),ROW(Table2[Vertical])-ROW(Table2[#Headers])),1)))} -> 4 | H6: =G6/B6 -> 0.074074074 | I6: {=IF(OR(I$2="",$A6=""),"",SUM(IF(FREQUENCY(IFERROR(IF(Table2[Vertical]=$A6,IF(Table2[Lead Status]=I$2,MATCH(Table2[Company / Account],Table2[Company / Account],0))),""),ROW(Table2[Vertical])-ROW(Table2[#Headers])),1)))} -> 0 | J6: =I6/B6 -> 0 | K6: {=IF(OR(K$2="",$A6=""),"",SUM(IF(FREQUENCY(IFERROR(IF(Table2[Vertical]=$A6,IF(Table2[Lead Status]=K$2,MATCH(Table2[Company / Account],Table2[Company / Account],0))),""),ROW(Table2[Vertical])-ROW(Table2[#Headers])),1)))}
A7: {=IFERROR(INDEX(Table2[Vertical],MATCH(1,IF(Table2[Vertical]<>"",IF(ISNA(MATCH(Table2[Vertical],A$1:A6,0)),1)),0)),"")} -> Retail - Grocery | B7: {=IF(A7="","",SUM(IF(FREQUENCY(IFERROR(IF(Table2[Vertical]=A7,MATCH(Table2[Company / Account],Table2[Company / Account],0)),""),ROW(Table2[Vertical])-ROW(Table2[#Headers])),1)))} -> 95 | C7: {=IF(OR(C$2="",$A7=""),"",SUM(IF(FREQUENCY(IFERROR(IF(Table2[Vertical]=$A7,IF(Table2[Lead Status]=C$2,MATCH(Table2[Company / Account],Table2[Company / Account],0))),""),ROW(Table2[Vertical])-ROW(Table2[#Headers])),1)))} -> 60 | D7: =C7/B7 -> 0.63157895 | E7: {=IF(OR(E$2="",$A7=""),"",SUM(IF(FREQUENCY(IFERROR(IF(Table2[Vertical]=$A7,IF(Table2[Lead Status]=E$2,MATCH(Table2[Company / Account],Table2[Company / Account],0))),""),ROW(Table2[Vertical])-ROW(Table2[#Headers])),1)))} -> 46 | F7: =E7/B7 -> 0.48421053 | G7: {=IF(OR(G$2="",$A7=""),"",SUM(IF(FREQUENCY(IFERROR(IF(Table2[Vertical]=$A7,IF(Table2[Lead Status]=G$2,MATCH(Table2[Company / Account],Table2[Company / Account],0))),""),ROW(Table2[Vertical])-ROW(Table2[#Headers])),1)))} -> 1 | H7: =G7/B7 -> 0.010526316 | I7: {=IF(OR(I$2="",$A7=""),"",SUM(IF(FREQUENCY(IFERROR(IF(Table2[Vertical]=$A7,IF(Table2[Lead Status]=I$2,MATCH(Table2[Company / Account],Table2[Company / Account],0))),""),ROW(Table2[Vertical])-ROW(Table2[#Headers])),1)))} -> 6 | J7: =I7/B7 -> 0.063157895 | K7: {=IF(OR(K$2="",$A7=""),"",SUM(IF(FREQUENCY(IFERROR(IF(Table2[Vertical]=$A7,IF(Table2[Lead Status]=K$2,MATCH(Table2[Company / Account],Table2[Company / Account],0))),""),ROW(Table2[Vertical])-ROW(Table2[#Headers])),1)))}
A8: {=IFERROR(INDEX(Table2[Vertical],MATCH(1,IF(Table2[Vertical]<>"",IF(ISNA(MATCH(Table2[Vertical],A$1:A7,0)),1)),0)),"")} -> Retail - Medium Box | B8: {=IF(A8="","",SUM(IF(FREQUENCY(IFERROR(IF(Table2[Vertical]=A8,MATCH(Table2[Company / Account],Table2[Company / Account],0)),""),ROW(Table2[Vertical])-ROW(Table2[#Headers])),1)))} -> 47 | C8: {=IF(OR(C$2="",$A8=""),"",SUM(IF(FREQUENCY(IFERROR(IF(Table2[Vertical]=$A8,IF(Table2[Lead Status]=C$2,MATCH(Table2[Company / Account],Table2[Company / Account],0))),""),ROW(Table2[Vertical])-ROW(Table2[#Headers])),1)))} -> 35 | D8: =C8/B8 -> 0.74468085 | E8: {=IF(OR(E$2="",$A8=""),"",SUM(IF(FREQUENCY(IFERROR(IF(Table2[Vertical]=$A8,IF(Table2[Lead Status]=E$2,MATCH(Table2[Company / Account],Table2[Company / Account],0))),""),ROW(Table2[Vertical])-ROW(Table2[#Headers])),1)))} -> 21 | F8: =E8/B8 -> 0.44680851 | G8: {=IF(OR(G$2="",$A8=""),"",SUM(IF(FREQUENCY(IFERROR(IF(Table2[Vertical]=$A8,IF(Table2[Lead Status]=G$2,MATCH(Table2[Company / Account],Table2[Company / Account],0))),""),ROW(Table2[Vertical])-ROW(Table2[#Headers])),1)))} -> 1 | H8: =G8/B8 -> 0.021276596 | I8: {=IF(OR(I$2="",$A8=""),"",SUM(IF(FREQUENCY(IFERROR(IF(Table2[Vertical]=$A8,IF(Table2[Lead Status]=I$2,MATCH(Table2[Company / Account],Table2[Company / Account],0))),""),ROW(Table2[Vertical])-ROW(Table2[#Headers])),1)))} -> 2 | J8: =I8/B8 -> 0.042553191 | K8: {=IF(OR(K$2="",$A8=""),"",SUM(IF(FREQUENCY(IFERROR(IF(Table2[Vertical]=$A8,IF(Table2[Lead Status]=K$2,MATCH(Table2[Company / Account],Table2[Company / Account],0))),""),ROW(Table2[Vertical])-ROW(Table2[#Headers])),1)))}
A9: {=IFERROR(INDEX(Table2[Vertical],MATCH(1,IF(Table2[Vertical]<>"",IF(ISNA(MATCH(Table2[Vertical],A$1:A8,0)),1)),0)),"")} -> Retail - Pharmacy | B9: {=IF(A9="","",SUM(IF(FREQUENCY(IFERROR(IF(Table2[Vertical]=A9,MATCH(Table2[Company / Account],Table2[Company / Account],0)),""),ROW(Table2[Vertical])-ROW(Table2[#Headers])),1)))} -> 7 | C9: {=IF(OR(C$2="",$A9=""),"",SUM(IF(FREQUENCY(IFERROR(IF(Table2[Vertical]=$A9,IF(Table2[Lead Status]=C$2,MATCH(Table2[Company / Account],Table2[Company / Account],0))),""),ROW(Table2[Vertical])-ROW(Table2[#Headers])),1)))} -> 4 | D9: =C9/B9 -> 0.57142857 | E9: {=IF(OR(E$2="",$A9=""),"",SUM(IF(FREQUENCY(IFERROR(IF(Table2[Vertical]=$A9,IF(Table2[Lead Status]=E$2,MATCH(Table2[Company / Account],Table2[Company / Account],0))),""),ROW(Table2[Vertical])-ROW(Table2[#Headers])),1)))} -> 4 | F9: =E9/B9 -> 0.57142857 | G9: {=IF(OR(G$2="",$A9=""),"",SUM(IF(FREQUENCY(IFERROR(IF(Table2[Vertical]=$A9,IF(Table2[Lead Status]=G$2,MATCH(Table2[Company / Account],Table2[Company / Account],0))),""),ROW(Table2[Vertical])-ROW(Table2[#Headers])),1)))} -> 0 | H9: =G9/B9 -> 0 | I9: {=IF(OR(I$2="",$A9=""),"",SUM(IF(FREQUENCY(IFERROR(IF(Table2[Vertical]=$A9,IF(Table2[Lead Status]=I$2,MATCH(Table2[Company / Account],Table2[Company / Account],0))),""),ROW(Table2[Vertical])-ROW(Table2[#Headers])),1)))} -> 0 | J9: =I9/B9 -> 0 | K9: {=IF(OR(K$2="",$A9=""),"",SUM(IF(FREQUENCY(IFERROR(IF(Table2[Vertical]=$A9,IF(Table2[Lead Status]=K$2,MATCH(Table2[Company / Account],Table2[Company / Account],0))),""),ROW(Table2[Vertical])-ROW(Table2[#Headers])),1)))}
A10: {=IFERROR(INDEX(Table2[Vertical],MATCH(1,IF(Table2[Vertical]<>"",IF(ISNA(MATCH(Table2[Vertical],A$1:A9,0)),1)),0)),"")} -> Retail - Small Box | B10: {=IF(A10="","",SUM(IF(FREQUENCY(IFERROR(IF(Table2[Vertical]=A10,MATCH(Table2[Company / Account],Table2[Company / Account],0)),""),ROW(Table2[Vertical])-ROW(Table2[#Headers])),1)))} -> 99 | C10: {=IF(OR(C$2="",$A10=""),"",SUM(IF(FREQUENCY(IFERROR(IF(Table2[Vertical]=$A10,IF(Table2[Lead Status]=C$2,MATCH(Table2[Company / Account],Table2[Company / Account],0))),""),ROW(Table2[Vertical])-ROW(Table2[#Headers])),1)))} -> 64 | D10: =C10/B10 -> 0.64646465 | E10: {=IF(OR(E$2="",$A10=""),"",SUM(IF(FREQUENCY(IFERROR(IF(Table2[Vertical]=$A10,IF(Table2[Lead Status]=E$2,MATCH(Table2[Company / Account],Table2[Company / Account],0))),""),ROW(Table2[Vertical])-ROW(Table2[#Headers])),1)))} -> 45 | F10: =E10/B10 -> 0.45454545 | G10: {=IF(OR(G$2="",$A10=""),"",SUM(IF(FREQUENCY(IFERROR(IF(Table2[Vertical]=$A10,IF(Table2[Lead Status]=G$2,MATCH(Table2[Company / Account],Table2[Company / Account],0))),""),ROW(Table2[Vertical])-ROW(Table2[#Headers])),1)))} -> 8 | H10: =G10/B10 -> 0.080808081 | I10: {=IF(OR(I$2="",$A10=""),"",SUM(IF(FREQUENCY(IFERROR(IF(Table2[Vertical]=$A10,IF(Table2[Lead Status]=I$2,MATCH(Table2[Company / Account],Table2[Company / Account],0))),""),ROW(Table2[Vertical])-ROW(Table2[#Headers])),1)))} -> 2 | J10: =I10/B10 -> 0.02020202 | K10: {=IF(OR(K$2="",$A10=""),"",SUM(IF(FREQUENCY(IFERROR(IF(Table2[Vertical]=$A10,IF(Table2[Lead Status]=K$2,MATCH(Table2[Company / Account],Table2[Company / Account],0))),""),ROW(Table2[Vertical])-ROW(Table2[#Headers])),1)))}
A12: Unique Vertical | B12: Total Unique Co. Count | C12: Count of Lead Status
C13: {=IFERROR(INDEX(Table2[Lead Status],MATCH(1,IF(Table2[Lead Status]<>"",IF(ISNA(MATCH(Table2[Lead Status],$A13:A13,0)),1)),0)),"")} -> Open - Not Contacted | D13: % of Total | E13: {=IFERROR(INDEX(Table2[Lead Status],MATCH(1,IF(Table2[Lead Status]<>"",IF(ISNA(MATCH(Table2[Lead Status],$A13:C13,0)),1)),0)),"")} -> Actively Working | F13: % of Total | G13: {=IFERROR(INDEX(Table2[Lead Status],MATCH(1,IF(Table2[Lead Status]<>"",IF(ISNA(MATCH(Table2[Lead Status],$A13:E13,0)),1)),0)),"")} -> Unqualified | H13: % of Total | I13: {=IFERROR(INDEX(Table2[Lead Status],MATCH(1,IF(Table2[Lead Status]<>"",IF(ISNA(MATCH(Table2[Lead Status],$A13:G13,0)),1)),0)),"")} -> Nurturing | J13: % of Total | K13: {=IFERROR(INDEX(Table2[Lead Status],MATCH(1,IF(Table2[Lead Status]<>"",IF(ISNA(MATCH(Table2[Lead Status],$A13:J13,0)),1)),0)),"")}
A14: {=IFERROR(INDEX(Table2[Lead Owner],MATCH(1,IF(Table2[Lead Owner]<>"",IF(ISNA(MATCH(Table2[Lead Owner],A$1:A13,0)),1)),0)),"")} -> Michael Donohue | B14: {=IF(A14="","",SUM(IF(FREQUENCY(IFERROR(IF(Table2[Lead Owner]=A14,MATCH(Table2[Company / Account],Table2[Company / Account],0)),""),ROW(Table2[Lead Owner])-ROW(Table2[#Headers])),1)))} -> 17 | C14: {=IF(OR(C$2="",$A14=""),"",SUM(IF(FREQUENCY(IFERROR(IF(Table2[Lead Owner]=$A14,IF(Table2[Lead Status]=C$2,MATCH(Table2[Company / Account],Table2[Company / Account],0))),""),ROW(Table2[Lead Owner])-ROW(Table2[#Headers])),1)))} -> 8 | D14: =C14/B14 -> 0.47058824 | E14: {=IF(OR(E$2="",$A14=""),"",SUM(IF(FREQUENCY(IFERROR(IF(Table2[Lead Owner]=$A14,IF(Table2[Lead Status]=E$2,MATCH(Table2[Company / Account],Table2[Company / Account],0))),""),ROW(Table2[Lead Owner])-ROW(Table2[#Headers])),1)))} -> 11 | F14: =E14/B14 -> 0.64705882 | G14: {=IF(OR(G$2="",$A14=""),"",SUM(IF(FREQUENCY(IFERROR(IF(Table2[Lead Owner]=$A14,IF(Table2[Lead Status]=G$2,MATCH(Table2[Company / Account],Table2[Company / Account],0))),""),ROW(Table2[Lead Owner])-ROW(Table2[#Headers])),1)))} -> 1 | H14: =G14/B14 -> 0.058823529 | I14: {=IF(OR(I$2="",$A14=""),"",SUM(IF(FREQUENCY(IFERROR(IF(Table2[Lead Owner]=$A14,IF(Table2[Lead Status]=I$2,MATCH(Table2[Company / Account],Table2[Company / Account],0))),""),ROW(Table2[Lead Owner])-ROW(Table2[#Headers])),1)))} -> 2 | J14: =I14/B14 -> 0.11764706 | K14: {=IF(OR(K$2="",$A14=""),"",SUM(IF(FREQUENCY(IFERROR(IF(Table2[Vertical]=$A14,IF(Table2[Lead Status]=K$2,MATCH(Table2[Company / Account],Table2[Company / Account],0))),""),ROW(Table2[Vertical])-ROW(Table2[#Headers])),1)))}
A15: {=IFERROR(INDEX(Table2[Lead Owner],MATCH(1,IF(Table2[Lead Owner]<>"",IF(ISNA(MATCH(Table2[Lead Owner],A$1:A14,0)),1)),0)),"")} -> Matt Creager | B15: {=IF(A15="","",SUM(IF(FREQUENCY(IFERROR(IF(Table2[Lead Owner]=A15,MATCH(Table2[Company / Account],Table2[Company / Account],0)),""),ROW(Table2[Lead Owner])-ROW(Table2[#Headers])),1)))} -> 72 | C15: {=IF(OR(C$2="",$A15=""),"",SUM(IF(FREQUENCY(IFERROR(IF(Table2[Lead Owner]=$A15,IF(Table2[Lead Status]=C$2,MATCH(Table2[Company / Account],Table2[Company / Account],0))),""),ROW(Table2[Lead Owner])-ROW(Table2[#Headers])),1)))} -> 52 | D15: =C15/B15 -> 0.72222222 | E15: {=IF(OR(E$2="",$A15=""),"",SUM(IF(FREQUENCY(IFERROR(IF(Table2[Lead Owner]=$A15,IF(Table2[Lead Status]=E$2,MATCH(Table2[Company / Account],Table2[Company / Account],0))),""),ROW(Table2[Lead Owner])-ROW(Table2[#Headers])),1)))} -> 22 | F15: =E15/B15 -> 0.30555556 | G15: {=IF(OR(G$2="",$A15=""),"",SUM(IF(FREQUENCY(IFERROR(IF(Table2[Lead Owner]=$A15,IF(Table2[Lead Status]=G$2,MATCH(Table2[Company / Account],Table2[Company / Account],0))),""),ROW(Table2[Lead Owner])-ROW(Table2[#Headers])),1)))} -> 8 | H15: =G15/B15 -> 0.11111111 | I15: {=IF(OR(I$2="",$A15=""),"",SUM(IF(FREQUENCY(IFERROR(IF(Table2[Lead Owner]=$A15,IF(Table2[Lead Status]=I$2,MATCH(Table2[Company / Account],Table2[Company / Account],0))),""),ROW(Table2[Lead Owner])-ROW(Table2[#Headers])),1)))} -> 11 | J15: =I15/B15 -> 0.15277778 | K15: {=IF(OR(K$2="",$A15=""),"",SUM(IF(FREQUENCY(IFERROR(IF(Table2[Vertical]=$A15,IF(Table2[Lead Status]=K$2,MATCH(Table2[Company / Account],Table2[Company / Account],0))),""),ROW(Table2[Vertical])-ROW(Table2[#Headers])),1)))}
A16: {=IFERROR(INDEX(Table2[Lead Owner],MATCH(1,IF(Table2[Lead Owner]<>"",IF(ISNA(MATCH(Table2[Lead Owner],A$1:A15,0)),1)),0)),"")} -> John Richmond | B16: {=IF(A16="","",SUM(IF(FREQUENCY(IFERROR(IF(Table2[Lead Owner]=A16,MATCH(Table2[Company / Account],Table2[Company / Account],0)),""),ROW(Table2[Lead Owner])-ROW(Table2[#Headers])),1)))} -> 87 | C16: {=IF(OR(C$2="",$A16=""),"",SUM(IF(FREQUENCY(IFERROR(IF(Table2[Lead Owner]=$A16,IF(Table2[Lead Status]=C$2,MATCH(Table2[Company / Account],Table2[Company / Account],0))),""),ROW(Table2[Lead Owner])-ROW(Table2[#Headers])),1)))} -> 79 | D16: =C16/B16 -> 0.90804598 | E16: {=IF(OR(E$2="",$A16=""),"",SUM(IF(FREQUENCY(IFERROR(IF(Table2[Lead Owner]=$A16,IF(Table2[Lead Status]=E$2,MATCH(Table2[Company / Account],Table2[Company / Account],0))),""),ROW(Table2[Lead Owner])-ROW(Table2[#Headers])),1)))} -> 9 | F16: =E16/B16 -> 0.10344828 | G16: {=IF(OR(G$2="",$A16=""),"",SUM(IF(FREQUENCY(IFERROR(IF(Table2[Lead Owner]=$A16,IF(Table2[Lead Status]=G$2,MATCH(Table2[Company / Account],Table2[Company / Account],0))),""),ROW(Table2[Lead Owner])-ROW(Table2[#Headers])),1)))} -> 6 | H16: =G16/B16 -> 0.068965517 | I16: {=IF(OR(I$2="",$A16=""),"",SUM(IF(FREQUENCY(IFERROR(IF(Table2[Lead Owner]=$A16,IF(Table2[Lead Status]=I$2,MATCH(Table2[Company / Account],Table2[Company / Account],0))),""),ROW(Table2[Lead Owner])-ROW(Table2[#Headers])),1)))} -> 0 | J16: =I16/B16 -> 0 | K16: {=IF(OR(K$2="",$A16=""),"",SUM(IF(FREQUENCY(IFERROR(IF(Table2[Vertical]=$A16,IF(Table2[Lead Status]=K$2,MATCH(Table2[Company / Account],Table2[Company / Account],0))),""),ROW(Table2[Vertical])-ROW(Table2[#Headers])),1)))}
A17: {=IFERROR(INDEX(Table2[Lead Owner],MATCH(1,IF(Table2[Lead Owner]<>"",IF(ISNA(MATCH(Table2[Lead Owner],A$1:A16,0)),1)),0)),"")} -> Mike Pluff | B17: {=IF(A17="","",SUM(IF(FREQUENCY(IFERROR(IF(Table2[Lead Owner]=A17,MATCH(Table2[Company / Account],Table2[Company / Account],0)),""),ROW(Table2[Lead Owner])-ROW(Table2[#Headers])),1)))} -> 107 | C17: {=IF(OR(C$2="",$A17=""),"",SUM(IF(FREQUENCY(IFERROR(IF(Table2[Lead Owner]=$A17,IF(Table2[Lead Status]=C$2,MATCH(Table2[Company / Account],Table2[Company / Account],0))),""),ROW(Table2[Lead Owner])-ROW(Table2[#Headers])),1)))} -> 96 | D17: =C17/B17 -> 0.89719626 | E17: {=IF(OR(E$2="",$A17=""),"",SUM(IF(FREQUENCY(IFERROR(IF(Table2[Lead Owner]=$A17,IF(Table2[Lead Status]=E$2,MATCH(Table2[Company / Account],Table2[Company / Account],0))),""),ROW(Table2[Lead Owner])-ROW(Table2[#Headers])),1)))} -> 26 | F17: =E17/B17 -> 0.24299065 | G17: {=IF(OR(G$2="",$A17=""),"",SUM(IF(FREQUENCY(IFERROR(IF(Table2[Lead Owner]=$A17,IF(Table2[Lead Status]=G$2,MATCH(Table2[Company / Account],Table2[Company / Account],0))),""),ROW(Table2[Lead Owner])-ROW(Table2[#Headers])),1)))} -> 1 | H17: =G17/B17 -> 0.0093457944 | I17: {=IF(OR(I$2="",$A17=""),"",SUM(IF(FREQUENCY(IFERROR(IF(Table2[Lead Owner]=$A17,IF(Table2[Lead Status]=I$2,MATCH(Table2[Company / Account],Table2[Company / Account],0))),""),ROW(Table2[Lead Owner])-ROW(Table2[#Headers])),1)))} -> 2 | J17: =I17/B17 -> 0.018691589 | K17: {=IF(OR(K$2="",$A17=""),"",SUM(IF(FREQUENCY(IFERROR(IF(Table2[Vertical]=$A17,IF(Table2[Lead Status]=K$2,MATCH(Table2[Company / Account],Table2[Company / Account],0))),""),ROW(Table2[Vertical])-ROW(Table2[#Headers])),1)))}
A18: {=IFERROR(INDEX(Table2[Lead Owner],MATCH(1,IF(Table2[Lead Owner]<>"",IF(ISNA(MATCH(Table2[Lead Owner],A$1:A17,0)),1)),0)),"")} -> Steven Shartzer | B18: {=IF(A18="","",SUM(IF(FREQUENCY(IFERROR(IF(Table2[Lead Owner]=A18,MATCH(Table2[Company / Account],Table2[Company / Account],0)),""),ROW(Table2[Lead Owner])-ROW(Table2[#Headers])),1)))} -> 58 | C18: {=IF(OR(C$2="",$A18=""),"",SUM(IF(FREQUENCY(IFERROR(IF(Table2[Lead Owner]=$A18,IF(Table2[Lead Status]=C$2,MATCH(Table2[Company / Account],Table2[Company / Account],0))),""),ROW(Table2[Lead Owner])-ROW(Table2[#Headers])),1)))} -> 29 | D18: =C18/B18 -> 0.5 | E18: {=IF(OR(E$2="",$A18=""),"",SUM(IF(FREQUENCY(IFERROR(IF(Table2[Lead Owner]=$A18,IF(Table2[Lead Status]=E$2,MATCH(Table2[Company / Account],Table2[Company / Account],0))),""),ROW(Table2[Lead Owner])-ROW(Table2[#Headers])),1)))} -> 39 | F18: =E18/B18 -> 0.67241379 | G18: {=IF(OR(G$2="",$A18=""),"",SUM(IF(FREQUENCY(IFERROR(IF(Table2[Lead Owner]=$A18,IF(Table2[Lead Status]=G$2,MATCH(Table2[Company / Account],Table2[Company / Account],0))),""),ROW(Table2[Lead Owner])-ROW(Table2[#Headers])),1)))} -> 1 | H18: =G18/B18 -> 0.017241379 | I18: {=IF(OR(I$2="",$A18=""),"",SUM(IF(FREQUENCY(IFERROR(IF(Table2[Lead Owner]=$A18,IF(Table2[Lead Status]=I$2,MATCH(Table2[Company / Account],Table2[Company / Account],0))),""),ROW(Table2[Lead Owner])-ROW(Table2[#Headers])),1)))} -> 2 | J18: =I18/B18 -> 0.034482759 | K18: {=IF(OR(K$2="",$A18=""),"",SUM(IF(FREQUENCY(IFERROR(IF(Table2[Vertical]=$A18,IF(Table2[Lead Status]=K$2,MATCH(Table2[Company / Account],Table2[Company / Account],0))),""),ROW(Table2[Vertical])-ROW(Table2[#Headers])),1)))}
A19: {=IFERROR(INDEX(Table2[Lead Owner],MATCH(1,IF(Table2[Lead Owner]<>"",IF(ISNA(MATCH(Table2[Lead Owner],A$1:A18,0)),1)),0)),"")} -> Jonathan Berger | B19: {=IF(A19="","",SUM(IF(FREQUENCY(IFERROR(IF(Table2[Lead Owner]=A19,MATCH(Table2[Company / Account],Table2[Company / Account],0)),""),ROW(Table2[Lead Owner])-ROW(Table2[#Headers])),1)))} -> 134 | C19: {=IF(OR(C$2="",$A19=""),"",SUM(IF(FREQUENCY(IFERROR(IF(Table2[Lead Owner]=$A19,IF(Table2[Lead Status]=C$2,MATCH(Table2[Company / Account],Table2[Company / Account],0))),""),ROW(Table2[Lead Owner])-ROW(Table2[#Headers])),1)))} -> 86 | D19: =C19/B19 -> 0.64179104 | E19: {=IF(OR(E$2="",$A19=""),"",SUM(IF(FREQUENCY(IFERROR(IF(Table2[Lead Owner]=$A19,IF(Table2[Lead Status]=E$2,MATCH(Table2[Company / Account],Table2[Company / Account],0))),""),ROW(Table2[Lead Owner])-ROW(Table2[#Headers])),1)))} -> 70 | F19: =E19/B19 -> 0.52238806 | G19: {=IF(OR(G$2="",$A19=""),"",SUM(IF(FREQUENCY(IFERROR(IF(Table2[Lead Owner]=$A19,IF(Table2[Lead Status]=G$2,MATCH(Table2[Company / Account],Table2[Company / Account],0))),""),ROW(Table2[Lead Owner])-ROW(Table2[#Headers])),1)))} -> 11 | H19: =G19/B19 -> 0.082089552 | I19: {=IF(OR(I$2="",$A19=""),"",SUM(IF(FREQUENCY(IFERROR(IF(Table2[Lead Owner]=$A19,IF(Table2[Lead Status]=I$2,MATCH(Table2[Company / Account],Table2[Company / Account],0))),""),ROW(Table2[Lead Owner])-ROW(Table2[#Headers])),1)))} -> 3 | J19: =I19/B19 -> 0.02238806 | K19: {=IF(OR(K$2="",$A19=""),"",SUM(IF(FREQUENCY(IFERROR(IF(Table2[Vertical]=$A19,IF(Table2[Lead Status]=K$2,MATCH(Table2[Company / Account],Table2[Company / Account],0))),""),ROW(Table2[Vertical])-ROW(Table2[#Headers])),1)))}
A20: {=IFERROR(INDEX(Table2[Lead Owner],MATCH(1,IF(Table2[Lead Owner]<>"",IF(ISNA(MATCH(Table2[Lead Owner],A$1:A19,0)),1)),0)),"")} -> Robert Giblett | B20: {=IF(A20="","",SUM(IF(FREQUENCY(IFERROR(IF(Table2[Lead Owner]=A20,MATCH(Table2[Company / Account],Table2[Company / Account],0)),""),ROW(Table2[Lead Owner])-ROW(Table2[#Headers])),1)))} -> 25 | C20: {=IF(OR(C$2="",$A20=""),"",SUM(IF(FREQUENCY(IFERROR(IF(Table2[Lead Owner]=$A20,IF(Table2[Lead Status]=C$2,MATCH(Table2[Company / Account],Table2[Company / Account],0))),""),ROW(Table2[Lead Owner])-ROW(Table2[#Headers])),1)))} -> 3 | D20: =C20/B20 -> 0.12 | E20: {=IF(OR(E$2="",$A20=""),"",SUM(IF(FREQUENCY(IFERROR(IF(Table2[Lead Owner]=$A20,IF(Table2[Lead Status]=E$2,MATCH(Table2[Company / Account],Table2[Company / Account],0))),""),ROW(Table2[Lead Owner])-ROW(Table2[#Headers])),1)))} -> 22 | F20: =E20/B20 -> 0.88 | G20: {=IF(OR(G$2="",$A20=""),"",SUM(IF(FREQUENCY(IFERROR(IF(Table2[Lead Owner]=$A20,IF(Table2[Lead Status]=G$2,MATCH(Table2[Company / Account],Table2[Company / Account],0))),""),ROW(Table2[Lead Owner])-ROW(Table2[#Headers])),1)))} -> 0 | H20: =G20/B20 -> 0 | I20: {=IF(OR(I$2="",$A20=""),"",SUM(IF(FREQUENCY(IFERROR(IF(Table2[Lead Owner]=$A20,IF(Table2[Lead Status]=I$2,MATCH(Table2[Company / Account],Table2[Company / Account],0))),""),ROW(Table2[Lead Owner])-ROW(Table2[#Headers])),1)))} -> 0 | J20: =I20/B20 -> 0 | K20: {=IF(OR(K$2="",$A20=""),"",SUM(IF(FREQUENCY(IFERROR(IF(Table2[Vertical]=$A20,IF(Table2[Lead Status]=K$2,MATCH(Table2[Company / Account],Table2[Company / Account],0))),""),ROW(Table2[Vertical])-ROW(Table2[#Headers])),1)))}
A21: {=IFERROR(INDEX(Table2[Lead Owner],MATCH(1,IF(Table2[Lead Owner]<>"",IF(ISNA(MATCH(Table2[Lead Owner],A$1:A20,0)),1)),0)),"")} -> Allen Scott | B21: {=IF(A21="","",SUM(IF(FREQUENCY(IFERROR(IF(Table2[Lead Owner]=A21,MATCH(Table2[Company / Account],Table2[Company / Account],0)),""),ROW(Table2[Lead Owner])-ROW(Table2[#Headers])),1)))} -> 3 | C21: {=IF(OR(C$2="",$A21=""),"",SUM(IF(FREQUENCY(IFERROR(IF(Table2[Lead Owner]=$A21,IF(Table2[Lead Status]=C$2,MATCH(Table2[Company / Account],Table2[Company / Account],0))),""),ROW(Table2[Lead Owner])-ROW(Table2[#Headers])),1)))} -> 3 | D21: =C21/B21 -> 1 | E21: {=IF(OR(E$2="",$A21=""),"",SUM(IF(FREQUENCY(IFERROR(IF(Table2[Lead Owner]=$A21,IF(Table2[Lead Status]=E$2,MATCH(Table2[Company / Account],Table2[Company / Account],0))),""),ROW(Table2[Lead Owner])-ROW(Table2[#Headers])),1)))} -> 0 | F21: =E21/B21 -> 0 | G21: {=IF(OR(G$2="",$A21=""),"",SUM(IF(FREQUENCY(IFERROR(IF(Table2[Lead Owner]=$A21,IF(Table2[Lead Status]=G$2,MATCH(Table2[Company / Account],Table2[Company / Account],0))),""),ROW(Table2[Lead Owner])-ROW(Table2[#Headers])),1)))} -> 0 | H21: =G21/B21 -> 0 | I21: {=IF(OR(I$2="",$A21=""),"",SUM(IF(FREQUENCY(IFERROR(IF(Table2[Lead Owner]=$A21,IF(Table2[Lead Status]=I$2,MATCH(Table2[Company / Account],Table2[Company / Account],0))),""),ROW(Table2[Lead Owner])-ROW(Table2[#Headers])),1)))} -> 0 | J21: =I21/B21 -> 0 | K21: {=IF(OR(K$2="",$A21=""),"",SUM(IF(FREQUENCY(IFERROR(IF(Table2[Vertical]=$A21,IF(Table2[Lead Status]=K$2,MATCH(Table2[Company / Account],Table2[Company / Account],0))),""),ROW(Table2[Vertical])-ROW(Table2[#Headers])),1)))}
